Workbook

Sheet Reminders-Updated 2021-03-05
A2: The following are some general notes and reminders last updated 03/05/2021
A5: Scoring and Certification Levels (Note that this is subject to change and may vary - always check the version of the rating system you're using
B6: Projects must achieve all preconditions as well as a certain number of points to earn different levels of certification:
C7: WELL Silver Certification: 50 points
C8: WELL Gold Certification: 60 points
C9: WELL Platinum Certification: 80 points
B10: Projects must earn a minimum of two points per concept Projects may pursue no more than 12 points per concept and
B11: no more than 100 points total across the ten concepts. Projects can also pursue an additional ten points for Innovation.
B12: At the point of submitting for Documentation Review, projects must submit a scorecard that contains a selection of
B13: points and Features in accordance with these rules.
B15: Points earned under W05 do not contribute to two point minimum
B17: One point earned under V03, 04, 05, 07, or 09 doesn't count toward the 2-point min
B19: https://v2wellcertifiedcom/v/en/overview
B21: WELL Core projects must achieve all preconditions as well as a certain number of points to earn different levels of certification:
C22: WELL Core Bronze Certification: 40 points
C23: WELL Core Silver Certification: 50 points
C24: WELL Core Gold Certification: 60 points
C25: WELL Core Platinum Certification: 80 points
C26: For WELL Core Certification, projects must earn a minimum of one point per concept Projects may earn no more than 12 points per concept
A29: Project Version (updated 10/28/2020):
B30: There are no typologies for WELL v2, except for WELL Core/WELL Campus/WELL Core Campus
B31: Use the addenda version shown in WELL Online for the project If a version isn't listed, contact Ops to obtain the addenda version
A32: Added 12/10/2019 | B32: If the project is another type, such as purely MFR, and Features are missing, this typically means they're not applicable and WELL Online has removed them. They can be listed as Not Applicable with typical stock text.
A35: Template functionality
B36: Manually adjust points in column G of the Review comments tab, as needed to account for Feature level point caps
C37: If a change is made, highlight the cell red for visibility during QC
B38: If additional space is needed in a Review Comment cell, insert a row underneath the current row the cell is in, then merge each cell in that row with the new cell directly underneath it
A39: Added 12/10/2019 | B39: Unhide the rows for S06, if attempted, in the Overview and Review Comments tabs
A40: Added 6/1/2020 | B40: Unhide the rows for Beta Features if attempted, in the Overview and Review Comments tabs
A41: Added 10/28/2020 | B41: OVERVIEW TAB UPDATES
C42: Overview tab reformatted - each significant point category is broken out into it's own sum
C43: Precondition pending cells at the top with the point count will go away when no preconditions are pending
C44: Red text will automatically become black once text has been entered in the applicable cell
C45: Overview tab is now protected to prevent unintentional changes: no password is needed
C46: Review phase drives additional options. Ensure to fill this out correctly.
C47: Point Headers are dynamic based on the Review phase selected.
C48: Overview tab page breaks should be correct at a zoom level of 100% at 1080 P (1920 x 1080) resolution. The page layout might need to be revised to Page Size A4 when printing to pdf if several Betas are pursued and those added Features force the page breaks to three pages.
D49: A4 should keep the overview part of the report to 2 pages and adjusts the text minimally. This will also be automatically adjusted by the user if they want to print the pdf to paper.
B50: REVIEW COMMENT TAB UPDATES
C51: Comment tab drop down for status is driven by the review phase from the overview tab. If an additional status is needed for a special reason, it can be added to the Lists tab in columns L, M, and N - add at the bottom and read instructions to the right.
...

Sheet Overview
C1: 2202025367 - Shenzhen Prince Bay Mixed-use Development DY04-02
D2: The WELL Building Standard v2.0 pilot (Q2 2021) WELL Core | I2: =SUM(U11:U290) -> 72 | J2: =VLOOKUP($D$4,Lists!$B$1:$E$19,2,FALSE) -> Anticipated
D3: =TODAY() -> 44879 | N3: Last updated 2021/03/05
D4: Final Precertification Review | I4: =SUM(S11:S290) -> 0 | J4: Pending Documentation | N4: Review phase drives additional options.
I5: =SUM(T11:T290) -> 0 | J5: Pending Documentation & On-Site | N5: Ensure to fill this out first.
I6: =SUM(R11:R290) -> 0 | J6: Anticipated, Pending On-Site
F7: =_xlfn.CONCAT(IF(SUM(W11:W290) > 0,"Preconditions Pending On-Site Assessment: ",""),IF(SUM(W11:W290)>0,IF(SUM(W11:W290) > 0,SUM(W11:W290),""),"")) | I7: =SUM(Q11:Q290) -> 0 | J7: =IF(VLOOKUP($D$4,Lists!$B$1:$E$19,3,FALSE)<> "",VLOOKUP($D$4,Lists!$B$1:$E$19,3,FALSE),"Not Anticipated") -> Not Anticipated
F8: =_xlfn.CONCAT(IF(SUM(V11:V290) > 0,"Preconditions Pending Documentation: ",""),IF(SUM(V11:V290)>0,IF(SUM(V11:V290) > 0,SUM(V11:V290),""),"")) | G8: =SUM(G290,G271,G225,G197,G169,G153,G135,G104,G88,G63,G40) -> 72 | H8: =SUM(H290,H271,H225,H197,H169,H153,H135,H104,H88,H63,H40) -> 0 | I8: =SUM(I290,I271,I225,I197,I169,I153,I135,I104,I88,I63,I40) -> 72 | J8: Total Points Attempted
A10: P/O | C10: Concept | D10: Type | E10: Feature | F10: Part | G10: Scorecard Points | H10: Pursuing | I10: Attempted | J10: Status | K10: =VLOOKUP(D4,Lists!B1:E15,2,FALSE) -> Anticipated | L10: =_xlfn.CONCAT(VLOOKUP($D$4,Lists!$B$1:$E19,3,FALSE),IF(OR(VLOOKUP($D$4,Lists!$B$1:$E19,4,FALSE) = "",VLOOKUP($D$4,Lists!$B$1:$E19,3,FALSE) = ""),""," or "),VLOOKUP($D$4,Lists!$B$1:$E19,4,FALSE)) -> Not Anticipated | Q10: Not Ant/Not Ach | R10: On-Site | S10: Pending Doc | T10: Pending doc/On-site | U10: Anticipated/achieved | V10: Precondition pending | W10: Preconditions Pend On-Site Only
A11: P | C11: AIR | D11: P | E11: A01. Fundamental Air Quality | F11: A01.1 Meet Thresholds for Particulate Matter | G11: ='Review Comments'!F10 -> 0 | H11: ='Review Comments'!G10 -> Required | I11: =IF(H11="Yes",G11,IF(H11="Required","Required","")) -> Required | J11: =IF('Review Comments'!H10=0,"",'Review Comments'!H10) -> Anticipated | K11: =IF(I11="Required","Required",IF(ISNUMBER(MATCH(J11,Lists!$H$2:$H$9,0)),I11,"")) -> Required | L11: =IF(I11="Required","Required",IF(ISNUMBER(MATCH(J11,Lists!$I$2:$I$9,0)),I11,IF(ISNUMBER(MATCH(J11,Lists!$J$2:$J$9,0)),I11,""))) -> Required | Q11: =IF(I11="Required",0,IF(ISNUMBER(MATCH(J11,Lists!$I$2:$I$4,0)),L11)) -> 0 | R11: =IF(I11="Required",0,IF(ISNUMBER(MATCH(J11,Lists!$K$2:$K$7,0)),L11)) -> 0 | S11: =IF(I11="Required",0,IF(ISNUMBER(MATCH(J11,Lists!$G$2:$G$4,0)),L11)) -> 0 | T11: =IF(I11="Required",0,IF(ISNUMBER(MATCH(J11,Lists!$G$7:$G$8,0)),L11)) -> 0 | U11: =IF(I11="Required",0,IF(ISNUMBER(MATCH(J11,Lists!$H$2:$H$4,0)),K11)) -> 0 | V11: =IF(A11="P",IF(IFERROR(SEARCH("Pending Documentation",J11),0)>0,IF(I11="Required",1,I11),0),0) -> 0 | W11: =IF(A11="P",IF(IFERROR(SEARCH("Pending On-site Assessment",J11),0)>0,IF(I11="Required",1,I11),0),0) -> 0
A12: P | F12: A01.2 Meet Thresholds for Organic Gases | G12: ='Review Comments'!F11 -> 0 | H12: ='Review Comments'!G11 -> Required | I12: =IF(H12="Yes",G12,IF(H12="Required","Required","")) -> Required | J12: =IF('Review Comments'!H11=0,"",'Review Comments'!H11) -> Anticipated | K12: =IF(I12="Required","Required",IF(ISNUMBER(MATCH(J12,Lists!$H$2:$H$9,0)),I12,"")) -> Required | L12: =IF(I12="Required","Required",IF(ISNUMBER(MATCH(J12,Lists!$I$2:$I$9,0)),I12,IF(ISNUMBER(MATCH(J12,Lists!$J$2:$J$9,0)),I12,""))) -> Required | Q12: =IF(I12="Required",0,IF(ISNUMBER(MATCH(J12,Lists!$I$2:$I$4,0)),L12)) -> 0 | R12: =IF(I12="Required",0,IF(ISNUMBER(MATCH(J12,Lists!$K$2:$K$7,0)),L12)) -> 0 | S12: =IF(I12="Required",0,IF(ISNUMBER(MATCH(J12,Lists!$G$2:$G$4,0)),L12)) -> 0 | T12: =IF(I12="Required",0,IF(ISNUMBER(MATCH(J12,Lists!$G$7:$G$8,0)),L12)) -> 0 | U12: =IF(I12="Required",0,IF(ISNUMBER(MATCH(J12,Lists!$H$2:$H$4,0)),K12)) -> 0 | V12: =IF(A12="P",IF(IFERROR(SEARCH("Pending Documentation",J12),0)>0,IF(I12="Required",1,I12),0),0) -> 0 | W12: =IF(A12="P",IF(IFERROR(SEARCH("Pending On-site Assessment",J12),0)>0,IF(I12="Required",1,I12),0),0) -> 0
A13: P | F13: A01.3 Meet Thresholds for Inorganic Gases | G13: ='Review Comments'!F12 -> 0 | H13: ='Review Comments'!G12 -> Required | I13: =IF(H13="Yes",G13,IF(H13="Required","Required","")) -> Required | J13: =IF('Review Comments'!H12=0,"",'Review Comments'!H12) -> Anticipated | K13: =IF(I13="Required","Required",IF(ISNUMBER(MATCH(J13,Lists!$H$2:$H$9,0)),I13,"")) -> Required | L13: =IF(I13="Required","Required",IF(ISNUMBER(MATCH(J13,Lists!$I$2:$I$9,0)),I13,IF(ISNUMBER(MATCH(J13,Lists!$J$2:$J$9,0)),I13,""))) -> Required | Q13: =IF(I13="Required",0,IF(ISNUMBER(MATCH(J13,Lists!$I$2:$I$4,0)),L13)) -> 0 | R13: =IF(I13="Required",0,IF(ISNUMBER(MATCH(J13,Lists!$K$2:$K$7,0)),L13)) -> 0 | S13: =IF(I13="Required",0,IF(ISNUMBER(MATCH(J13,Lists!$G$2:$G$4,0)),L13)) -> 0 | T13: =IF(I13="Required",0,IF(ISNUMBER(MATCH(J13,Lists!$G$7:$G$8,0)),L13)) -> 0 | U13: =IF(I13="Required",0,IF(ISNUMBER(MATCH(J13,Lists!$H$2:$H$4,0)),K13)) -> 0 | V13: =IF(A13="P",IF(IFERROR(SEARCH("Pending Documentation",J13),0)>0,IF(I13="Required",1,I13),0),0) -> 0 | W13: =IF(A13="P",IF(IFERROR(SEARCH("Pending On-site Assessment",J13),0)>0,IF(I13="Required",1,I13),0),0) -> 0
A14: P | F14: A01.4 Meet Radon Threshold | G14: ='Review Comments'!F13 -> 0 | H14: ='Review Comments'!G13 -> Required | I14: =IF(H14="Yes",G14,IF(H14="Required","Required","")) -> Required | J14: =IF('Review Comments'!H13=0,"",'Review Comments'!H13) -> Anticipated | K14: =IF(I14="Required","Required",IF(ISNUMBER(MATCH(J14,Lists!$H$2:$H$9,0)),I14,"")) -> Required | L14: =IF(I14="Required","Required",IF(ISNUMBER(MATCH(J14,Lists!$I$2:$I$9,0)),I14,IF(ISNUMBER(MATCH(J14,Lists!$J$2:$J$9,0)),I14,""))) -> Required | Q14: =IF(I14="Required",0,IF(ISNUMBER(MATCH(J14,Lists!$I$2:$I$4,0)),L14)) -> 0 | R14: =IF(I14="Required",0,IF(ISNUMBER(MATCH(J14,Lists!$K$2:$K$7,0)),L14)) -> 0 | S14: =IF(I14="Required",0,IF(ISNUMBER(MATCH(J14,Lists!$G$2:$G$4,0)),L14)) -> 0 | T14: =IF(I14="Required",0,IF(ISNUMBER(MATCH(J14,Lists!$G$7:$G$8,0)),L14)) -> 0 | U14: =IF(I14="Required",0,IF(ISNUMBER(MATCH(J14,Lists!$H$2:$H$4,0)),K14)) -> 0 | V14: =IF(A14="P",IF(IFERROR(SEARCH("Pending Documentation",J14),0)>0,IF(I14="Required",1,I14),0),0) -> 0 | W14: =IF(A14="P",IF(IFERROR(SEARCH("Pending On-site Assessment",J14),0)>0,IF(I14="Required",1,I14),0),0) -> 0
A15: P | F15: A01.5 Monitor Fundamental Air Parameters | G15: ='Review Comments'!F14 -> 0 | H15: ='Review Comments'!G14 -> Required | I15: =IF(H15="Yes",G15,IF(H15="Required","Required","")) -> Required | J15: =IF('Review Comments'!H14=0,"",'Review Comments'!H14) -> Anticipated | K15: =IF(I15="Required","Required",IF(ISNUMBER(MATCH(J15,Lists!$H$2:$H$9,0)),I15,"")) -> Required | L15: =IF(I15="Required","Required",IF(ISNUMBER(MATCH(J15,Lists!$I$2:$I$9,0)),I15,IF(ISNUMBER(MATCH(J15,Lists!$J$2:$J$9,0)),I15,""))) -> Required | Q15: =IF(I15="Required",0,IF(ISNUMBER(MATCH(J15,Lists!$I$2:$I$4,0)),L15)) -> 0 | R15: =IF(I15="Required",0,IF(ISNUMBER(MATCH(J15,Lists!$K$2:$K$7,0)),L15)) -> 0 | S15: =IF(I15="Required",0,IF(ISNUMBER(MATCH(J15,Lists!$G$2:$G$4,0)),L15)) -> 0 | T15: =IF(I15="Required",0,IF(ISNUMBER(MATCH(J15,Lists!$G$7:$G$8,0)),L15)) -> 0 | U15: =IF(I15="Required",0,IF(ISNUMBER(MATCH(J15,Lists!$H$2:$H$4,0)),K15)) -> 0 | V15: =IF(A15="P",IF(IFERROR(SEARCH("Pending Documentation",J15),0)>0,IF(I15="Required",1,I15),0),0) -> 0 | W15: =IF(A15="P",IF(IFERROR(SEARCH("Pending On-site Assessment",J15),0)>0,IF(I15="Required",1,I15),0),0) -> 0
A16: P | D16: P | E16: A02. Smoke-Free Environment | F16: A02.1 Prohibit Indoor Smoking | G16: ='Review Comments'!F15 -> 0 | H16: ='Review Comments'!G15 -> Required | I16: =IF(H16="Yes",G16,IF(H16="Required","Required","")) -> Required | J16: =IF('Review Comments'!H15=0,"",'Review Comments'!H15) -> Anticipated | K16: =IF(I16="Required","Required",IF(ISNUMBER(MATCH(J16,Lists!$H$2:$H$9,0)),I16,"")) -> Required | L16: =IF(I16="Required","Required",IF(ISNUMBER(MATCH(J16,Lists!$I$2:$I$9,0)),I16,IF(ISNUMBER(MATCH(J16,Lists!$J$2:$J$9,0)),I16,""))) -> Required | Q16: =IF(I16="Required",0,IF(ISNUMBER(MATCH(J16,Lists!$I$2:$I$4,0)),L16)) -> 0 | R16: =IF(I16="Required",0,IF(ISNUMBER(MATCH(J16,Lists!$K$2:$K$7,0)),L16)) -> 0 | S16: =IF(I16="Required",0,IF(ISNUMBER(MATCH(J16,Lists!$G$2:$G$4,0)),L16)) -> 0 | T16: =IF(I16="Required",0,IF(ISNUMBER(MATCH(J16,Lists!$G$7:$G$8,0)),L16)) -> 0 | U16: =IF(I16="Required",0,IF(ISNUMBER(MATCH(J16,Lists!$H$2:$H$4,0)),K16)) -> 0 | V16: =IF(A16="P",IF(IFERROR(SEARCH("Pending Documentation",J16),0)>0,IF(I16="Required",1,I16),0),0) -> 0 | W16: =IF(A16="P",IF(IFERROR(SEARCH("Pending On-site Assessment",J16),0)>0,IF(I16="Required",1,I16),0),0) -> 0
A17: P | F17: A02.2 Prohibit Outdoor Smoking | G17: ='Review Comments'!F16 -> 0 | H17: ='Review Comments'!G16 -> Required | I17: =IF(H17="Yes",G17,IF(H17="Required","Required","")) -> Required | J17: =IF('Review Comments'!H16=0,"",'Review Comments'!H16) -> Anticipated | K17: =IF(I17="Required","Required",IF(ISNUMBER(MATCH(J17,Lists!$H$2:$H$9,0)),I17,"")) -> Required | L17: =IF(I17="Required","Required",IF(ISNUMBER(MATCH(J17,Lists!$I$2:$I$9,0)),I17,IF(ISNUMBER(MATCH(J17,Lists!$J$2:$J$9,0)),I17,""))) -> Required | Q17: =IF(I17="Required",0,IF(ISNUMBER(MATCH(J17,Lists!$I$2:$I$4,0)),L17)) -> 0 | R17: =IF(I17="Required",0,IF(ISNUMBER(MATCH(J17,Lists!$K$2:$K$7,0)),L17)) -> 0 | S17: =IF(I17="Required",0,IF(ISNUMBER(MATCH(J17,Lists!$G$2:$G$4,0)),L17)) -> 0 | T17: =IF(I17="Required",0,IF(ISNUMBER(MATCH(J17,Lists!$G$7:$G$8,0)),L17)) -> 0 | U17: =IF(I17="Required",0,IF(ISNUMBER(MATCH(J17,Lists!$H$2:$H$4,0)),K17)) -> 0 | V17: =IF(A17="P",IF(IFERROR(SEARCH("Pending Documentation",J17),0)>0,IF(I17="Required",1,I17),0),0) -> 0 | W17: =IF(A17="P",IF(IFERROR(SEARCH("Pending On-site Assessment",J17),0)>0,IF(I17="Required",1,I17),0),0) -> 0
A18: P | D18: P | E18: A03. Ventilation Effectiveness | F18: A03.1 Ensure Adequate Ventilation | G18: ='Review Comments'!F17 -> 0 | H18: ='Review Comments'!G17 -> Required | I18: =IF(H18="Yes",G18,IF(H18="Required","Required","")) -> Required | J18: =IF('Review Comments'!H17=0,"",'Review Comments'!H17) -> Anticipated | K18: =IF(I18="Required","Required",IF(ISNUMBER(MATCH(J18,Lists!$H$2:$H$9,0)),I18,"")) -> Required | L18: =IF(I18="Required","Required",IF(ISNUMBER(MATCH(J18,Lists!$I$2:$I$9,0)),I18,IF(ISNUMBER(MATCH(J18,Lists!$J$2:$J$9,0)),I18,""))) -> Required | Q18: =IF(I18="Required",0,IF(ISNUMBER(MATCH(J18,Lists!$I$2:$I$4,0)),L18)) -> 0 | R18: =IF(I18="Required",0,IF(ISNUMBER(MATCH(J18,Lists!$K$2:$K$7,0)),L18)) -> 0 | S18: =IF(I18="Required",0,IF(ISNUMBER(MATCH(J18,Lists!$G$2:$G$4,0)),L18)) -> 0 | T18: =IF(I18="Required",0,IF(ISNUMBER(MATCH(J18,Lists!$G$7:$G$8,0)),L18)) -> 0 | U18: =IF(I18="Required",0,IF(ISNUMBER(MATCH(J18,Lists!$H$2:$H$4,0)),K18)) -> 0 | V18: =IF(A18="P",IF(IFERROR(SEARCH("Pending Documentation",J18),0)>0,IF(I18="Required",1,I18),0),0) -> 0 | W18: =IF(A18="P",IF(IFERROR(SEARCH("Pending On-site Assessment",J18),0)>0,IF(I18="Required",1,I18),0),0) -> 0
A19: P | F19: A03.2 Conduct System Balancing | G19: ='Review Comments'!F18 -> 0 | H19: ='Review Comments'!G18 -> Required | I19: =IF(H19="Yes",G19,IF(H19="Required","Required","")) -> Required | J19: =IF('Review Comments'!H18=0,"",'Review Comments'!H18) -> Anticipated | K19: =IF(I19="Required","Required",IF(ISNUMBER(MATCH(J19,Lists!$H$2:$H$9,0)),I19,"")) -> Required | L19: =IF(I19="Required","Required",IF(ISNUMBER(MATCH(J19,Lists!$I$2:$I$9,0)),I19,IF(ISNUMBER(MATCH(J19,Lists!$J$2:$J$9,0)),I19,""))) -> Required | Q19: =IF(I19="Required",0,IF(ISNUMBER(MATCH(J19,Lists!$I$2:$I$4,0)),L19)) -> 0 | R19: =IF(I19="Required",0,IF(ISNUMBER(MATCH(J19,Lists!$K$2:$K$7,0)),L19)) -> 0 | S19: =IF(I19="Required",0,IF(ISNUMBER(MATCH(J19,Lists!$G$2:$G$4,0)),L19)) -> 0 | T19: =IF(I19="Required",0,IF(ISNUMBER(MATCH(J19,Lists!$G$7:$G$8,0)),L19)) -> 0 | U19: =IF(I19="Required",0,IF(ISNUMBER(MATCH(J19,Lists!$H$2:$H$4,0)),K19)) -> 0 | V19: =IF(A19="P",IF(IFERROR(SEARCH("Pending Documentation",J19),0)>0,IF(I19="Required",1,I19),0),0) -> 0 | W19: =IF(A19="P",IF(IFERROR(SEARCH("Pending On-site Assessment",J19),0)>0,IF(I19="Required",1,I19),0),0) -> 0
A20: P | D20: P | E20: A04. Construction Pollution Management | F20: A04.1 Mitigate Construction Pollution | G20: ='Review Comments'!F19 -> 0 | H20: ='Review Comments'!G19 -> Required | I20: =IF(H20="Yes",G20,IF(H20="Required","Required","")) -> Required | J20: =IF('Review Comments'!H19=0,"",'Review Comments'!H19) -> Anticipated | K20: =IF(I20="Required","Required",IF(ISNUMBER(MATCH(J20,Lists!$H$2:$H$9,0)),I20,"")) -> Required | L20: =IF(I20="Required","Required",IF(ISNUMBER(MATCH(J20,Lists!$I$2:$I$9,0)),I20,IF(ISNUMBER(MATCH(J20,Lists!$J$2:$J$9,0)),I20,""))) -> Required | Q20: =IF(I20="Required",0,IF(ISNUMBER(MATCH(J20,Lists!$I$2:$I$4,0)),L20)) -> 0 | R20: =IF(I20="Required",0,IF(ISNUMBER(MATCH(J20,Lists!$K$2:$K$7,0)),L20)) -> 0 | S20: =IF(I20="Required",0,IF(ISNUMBER(MATCH(J20,Lists!$G$2:$G$4,0)),L20)) -> 0 | T20: =IF(I20="Required",0,IF(ISNUMBER(MATCH(J20,Lists!$G$7:$G$8,0)),L20)) -> 0 | U20: =IF(I20="Required",0,IF(ISNUMBER(MATCH(J20,Lists!$H$2:$H$4,0)),K20)) -> 0 | V20: =IF(A20="P",IF(IFERROR(SEARCH("Pending Documentation",J20),0)>0,IF(I20="Required",1,I20),0),0) -> 0 | W20: =IF(A20="P",IF(IFERROR(SEARCH("Pending On-site Assessment",J20),0)>0,IF(I20="Required",1,I20),0),0) -> 0
A21: O | D21: O | E21: A05. Enhanced Air Quality | F21: A05.1 / 2 Points Meet Enhanced Thresholds for Particulate Matter | G21: ='Review Comments'!F20 -> 1 | H21: ='Review Comments'!G20 -> Yes | I21: =IF(H21="Yes",G21,IF(H21="Required","Required","")) -> 1 | J21: =IF('Review Comments'!H20=0,"",'Review Comments'!H20) -> Anticipated | K21: =IF(I21="Required","Required",IF(ISNUMBER(MATCH(J21,Lists!$H$2:$H$9,0)),I21,"")) -> 1 | L21: =IF(I21="Required","Required",IF(ISNUMBER(MATCH(J21,Lists!$I$2:$I$9,0)),I21,IF(ISNUMBER(MATCH(J21,Lists!$J$2:$J$9,0)),I21,""))) | Q21: =IF(I21="Required",0,IF(ISNUMBER(MATCH(J21,Lists!$I$2:$I$4,0)),L21)) -> FALSE | R21: =IF(I21="Required",0,IF(ISNUMBER(MATCH(J21,Lists!$K$2:$K$7,0)),L21)) -> FALSE | S21: =IF(I21="Required",0,IF(ISNUMBER(MATCH(J21,Lists!$G$2:$G$4,0)),L21)) -> FALSE | T21: =IF(I21="Required",0,IF(ISNUMBER(MATCH(J21,Lists!$G$7:$G$8,0)),L21)) -> FALSE | U21: =IF(I21="Required",0,IF(ISNUMBER(MATCH(J21,Lists!$H$2:$H$4,0)),K21)) -> 1 | V21: =IF(A21="P",IF(IFERROR(SEARCH("Pending Documentation",J21),0)>0,IF(I21="Required",1,I21),0),0) -> 0 | W21: =IF(A21="P",IF(IFERROR(SEARCH("Pending On-site Assessment",J21),0)>0,IF(I21="Required",1,I21),0),0) -> 0
A22: O | F22: A05.2 / 1 Point Meet Enhanced Thresholds for Organic Gases | G22: ='Review Comments'!F21 -> 0 | H22: ='Review Comments'!G21 -> No | I22: =IF(H22="Yes",G22,IF(H22="Required","Required","")) | J22: =IF('Review Comments'!H21=0,"",'Review Comments'!H21) -> Not Attempted | K22: =IF(I22="Required","Required",IF(ISNUMBER(MATCH(J22,Lists!$H$2:$H$9,0)),I22,"")) | L22: =IF(I22="Required","Required",IF(ISNUMBER(MATCH(J22,Lists!$I$2:$I$9,0)),I22,IF(ISNUMBER(MATCH(J22,Lists!$J$2:$J$9,0)),I22,""))) | Q22: =IF(I22="Required",0,IF(ISNUMBER(MATCH(J22,Lists!$I$2:$I$4,0)),L22)) -> FALSE | R22: =IF(I22="Required",0,IF(ISNUMBER(MATCH(J22,Lists!$K$2:$K$7,0)),L22)) -> FALSE | S22: =IF(I22="Required",0,IF(ISNUMBER(MATCH(J22,Lists!$G$2:$G$4,0)),L22)) -> FALSE | T22: =IF(I22="Required",0,IF(ISNUMBER(MATCH(J22,Lists!$G$7:$G$8,0)),L22)) -> FALSE | U22: =IF(I22="Required",0,IF(ISNUMBER(MATCH(J22,Lists!$H$2:$H$4,0)),K22)) -> FALSE | V22: =IF(A22="P",IF(IFERROR(SEARCH("Pending Documentation",J22),0)>0,IF(I22="Required",1,I22),0),0) -> 0 | W22: =IF(A22="P",IF(IFERROR(SEARCH("Pending On-site Assessment",J22),0)>0,IF(I22="Required",1,I22),0),0) -> 0
A23: O | F23: A05.3 / 1 Point Meet Enhanced Thresholds for Inorganic Gases | G23: ='Review Comments'!F22 -> 0 | H23: ='Review Comments'!G22 -> No | I23: =IF(H23="Yes",G23,IF(H23="Required","Required","")) | J23: =IF('Review Comments'!H22=0,"",'Review Comments'!H22) -> Not Attempted | K23: =IF(I23="Required","Required",IF(ISNUMBER(MATCH(J23,Lists!$H$2:$H$9,0)),I23,"")) | L23: =IF(I23="Required","Required",IF(ISNUMBER(MATCH(J23,Lists!$I$2:$I$9,0)),I23,IF(ISNUMBER(MATCH(J23,Lists!$J$2:$J$9,0)),I23,""))) | Q23: =IF(I23="Required",0,IF(ISNUMBER(MATCH(J23,Lists!$I$2:$I$4,0)),L23)) -> FALSE | R23: =IF(I23="Required",0,IF(ISNUMBER(MATCH(J23,Lists!$K$2:$K$7,0)),L23)) -> FALSE | S23: =IF(I23="Required",0,IF(ISNUMBER(MATCH(J23,Lists!$G$2:$G$4,0)),L23)) -> FALSE | T23: =IF(I23="Required",0,IF(ISNUMBER(MATCH(J23,Lists!$G$7:$G$8,0)),L23)) -> FALSE | U23: =IF(I23="Required",0,IF(ISNUMBER(MATCH(J23,Lists!$H$2:$H$4,0)),K23)) -> FALSE | V23: =IF(A23="P",IF(IFERROR(SEARCH("Pending Documentation",J23),0)>0,IF(I23="Required",1,I23),0),0) -> 0 | W23: =IF(A23="P",IF(IFERROR(SEARCH("Pending On-site Assessment",J23),0)>0,IF(I23="Required",1,I23),0),0) -> 0
A24: O | D24: O | E24: A06. Enhanced Ventilation | F24: A06.1 / 3 Points Increase Outdoor Air Supply | G24: ='Review Comments'!F23 -> 1 | H24: ='Review Comments'!G23 -> Yes | I24: =IF(H24="Yes",G24,IF(H24="Required","Required","")) -> 1 | J24: =IF('Review Comments'!H23=0,"",'Review Comments'!H23) -> Anticipated | K24: =IF(I24="Required","Required",IF(ISNUMBER(MATCH(J24,Lists!$H$2:$H$9,0)),I24,"")) -> 1 | L24: =IF(I24="Required","Required",IF(ISNUMBER(MATCH(J24,Lists!$I$2:$I$9,0)),I24,IF(ISNUMBER(MATCH(J24,Lists!$J$2:$J$9,0)),I24,""))) | Q24: =IF(I24="Required",0,IF(ISNUMBER(MATCH(J24,Lists!$I$2:$I$4,0)),L24)) -> FALSE | R24: =IF(I24="Required",0,IF(ISNUMBER(MATCH(J24,Lists!$K$2:$K$7,0)),L24)) -> FALSE | S24: =IF(I24="Required",0,IF(ISNUMBER(MATCH(J24,Lists!$G$2:$G$4,0)),L24)) -> FALSE | T24: =IF(I24="Required",0,IF(ISNUMBER(MATCH(J24,Lists!$G$7:$G$8,0)),L24)) -> FALSE | U24: =IF(I24="Required",0,IF(ISNUMBER(MATCH(J24,Lists!$H$2:$H$4,0)),K24)) -> 1 | V24: =IF(A24="P",IF(IFERROR(SEARCH("Pending Documentation",J24),0)>0,IF(I24="Required",1,I24),0),0) -> 0 | W24: =IF(A24="P",IF(IFERROR(SEARCH("Pending On-site Assessment",J24),0)>0,IF(I24="Required",1,I24),0),0) -> 0
A25: O | F25: A06.2 / 3 Points Implement Demand-Controlled Ventilation | G25: ='Review Comments'!F24 -> 1 | H25: ='Review Comments'!G24 -> Yes | I25: =IF(H25="Yes",G25,IF(H25="Required","Required","")) -> 1 | J25: =IF('Review Comments'!H24=0,"",'Review Comments'!H24) -> Anticipated | K25: =IF(I25="Required","Required",IF(ISNUMBER(MATCH(J25,Lists!$H$2:$H$9,0)),I25,"")) -> 1 | L25: =IF(I25="Required","Required",IF(ISNUMBER(MATCH(J25,Lists!$I$2:$I$9,0)),I25,IF(ISNUMBER(MATCH(J25,Lists!$J$2:$J$9,0)),I25,""))) | Q25: =IF(I25="Required",0,IF(ISNUMBER(MATCH(J25,Lists!$I$2:$I$4,0)),L25)) -> FALSE | R25: =IF(I25="Required",0,IF(ISNUMBER(MATCH(J25,Lists!$K$2:$K$7,0)),L25)) -> FALSE | S25: =IF(I25="Required",0,IF(ISNUMBER(MATCH(J25,Lists!$G$2:$G$4,0)),L25)) -> FALSE | T25: =IF(I25="Required",0,IF(ISNUMBER(MATCH(J25,Lists!$G$7:$G$8,0)),L25)) -> FALSE | U25: =IF(I25="Required",0,IF(ISNUMBER(MATCH(J25,Lists!$H$2:$H$4,0)),K25)) -> 1 | V25: =IF(A25="P",IF(IFERROR(SEARCH("Pending Documentation",J25),0)>0,IF(I25="Required",1,I25),0),0) -> 0 | W25: =IF(A25="P",IF(IFERROR(SEARCH("Pending On-site Assessment",J25),0)>0,IF(I25="Required",1,I25),0),0) -> 0
A26: O | F26: A06.3 / 1 Point Implement Displacement Ventilation | G26: ='Review Comments'!F25 -> 0 | H26: ='Review Comments'!G25 -> No | I26: =IF(H26="Yes",G26,IF(H26="Required","Required","")) | J26: =IF('Review Comments'!H25=0,"",'Review Comments'!H25) -> Not Attempted | K26: =IF(I26="Required","Required",IF(ISNUMBER(MATCH(J26,Lists!$H$2:$H$9,0)),I26,"")) | L26: =IF(I26="Required","Required",IF(ISNUMBER(MATCH(J26,Lists!$I$2:$I$9,0)),I26,IF(ISNUMBER(MATCH(J26,Lists!$J$2:$J$9,0)),I26,""))) | Q26: =IF(I26="Required",0,IF(ISNUMBER(MATCH(J26,Lists!$I$2:$I$4,0)),L26)) -> FALSE | R26: =IF(I26="Required",0,IF(ISNUMBER(MATCH(J26,Lists!$K$2:$K$7,0)),L26)) -> FALSE | S26: =IF(I26="Required",0,IF(ISNUMBER(MATCH(J26,Lists!$G$2:$G$4,0)),L26)) -> FALSE | T26: =IF(I26="Required",0,IF(ISNUMBER(MATCH(J26,Lists!$G$7:$G$8,0)),L26)) -> FALSE | U26: =IF(I26="Required",0,IF(ISNUMBER(MATCH(J26,Lists!$H$2:$H$4,0)),K26)) -> FALSE | V26: =IF(A26="P",IF(IFERROR(SEARCH("Pending Documentation",J26),0)>0,IF(I26="Required",1,I26),0),0) -> 0 | W26: =IF(A26="P",IF(IFERROR(SEARCH("Pending On-site Assessment",J26),0)>0,IF(I26="Required",1,I26),0),0) -> 0
A27: O | F27: A06.4 / 3 Points Implement Advanced Air Distribution | G27: ='Review Comments'!F26 -> 0 | H27: ='Review Comments'!G26 -> No | I27: =IF(H27="Yes",G27,IF(H27="Required","Required","")) | J27: =IF('Review Comments'!H26=0,"",'Review Comments'!H26) -> Not Attempted | K27: =IF(I27="Required","Required",IF(ISNUMBER(MATCH(J27,Lists!$H$2:$H$9,0)),I27,"")) | L27: =IF(I27="Required","Required",IF(ISNUMBER(MATCH(J27,Lists!$I$2:$I$9,0)),I27,IF(ISNUMBER(MATCH(J27,Lists!$J$2:$J$9,0)),I27,""))) | Q27: =IF(I27="Required",0,IF(ISNUMBER(MATCH(J27,Lists!$I$2:$I$4,0)),L27)) -> FALSE | R27: =IF(I27="Required",0,IF(ISNUMBER(MATCH(J27,Lists!$K$2:$K$7,0)),L27)) -> FALSE | S27: =IF(I27="Required",0,IF(ISNUMBER(MATCH(J27,Lists!$G$2:$G$4,0)),L27)) -> FALSE | T27: =IF(I27="Required",0,IF(ISNUMBER(MATCH(J27,Lists!$G$7:$G$8,0)),L27)) -> FALSE | U27: =IF(I27="Required",0,IF(ISNUMBER(MATCH(J27,Lists!$H$2:$H$4,0)),K27)) -> FALSE | V27: =IF(A27="P",IF(IFERROR(SEARCH("Pending Documentation",J27),0)>0,IF(I27="Required",1,I27),0),0) -> 0 | W27: =IF(A27="P",IF(IFERROR(SEARCH("Pending On-site Assessment",J27),0)>0,IF(I27="Required",1,I27),0),0) -> 0
A28: O | D28: O | E28: A07. Operable Windows | F28: A07.1 / 1 Point Provide Operable Windows | G28: ='Review Comments'!F27 -> 0 | H28: ='Review Comments'!G27 -> No | I28: =IF(H28="Yes",G28,IF(H28="Required","Required","")) | J28: =IF('Review Comments'!H27=0,"",'Review Comments'!H27) -> Not Attempted | K28: =IF(I28="Required","Required",IF(ISNUMBER(MATCH(J28,Lists!$H$2:$H$9,0)),I28,"")) | L28: =IF(I28="Required","Required",IF(ISNUMBER(MATCH(J28,Lists!$I$2:$I$9,0)),I28,IF(ISNUMBER(MATCH(J28,Lists!$J$2:$J$9,0)),I28,""))) | Q28: =IF(I28="Required",0,IF(ISNUMBER(MATCH(J28,Lists!$I$2:$I$4,0)),L28)) -> FALSE | R28: =IF(I28="Required",0,IF(ISNUMBER(MATCH(J28,Lists!$K$2:$K$7,0)),L28)) -> FALSE | S28: =IF(I28="Required",0,IF(ISNUMBER(MATCH(J28,Lists!$G$2:$G$4,0)),L28)) -> FALSE | T28: =IF(I28="Required",0,IF(ISNUMBER(MATCH(J28,Lists!$G$7:$G$8,0)),L28)) -> FALSE | U28: =IF(I28="Required",0,IF(ISNUMBER(MATCH(J28,Lists!$H$2:$H$4,0)),K28)) -> FALSE | V28: =IF(A28="P",IF(IFERROR(SEARCH("Pending Documentation",J28),0)>0,IF(I28="Required",1,I28),0),0) -> 0 | W28: =IF(A28="P",IF(IFERROR(SEARCH("Pending On-site Assessment",J28),0)>0,IF(I28="Required",1,I28),0),0) -> 0
A29: O | F29: A07.2 / 1 Point Manage Window Use | G29: ='Review Comments'!F28 -> 0 | H29: ='Review Comments'!G28 -> No | I29: =IF(H29="Yes",G29,IF(H29="Required","Required","")) | J29: =IF('Review Comments'!H28=0,"",'Review Comments'!H28) -> Not Attempted | K29: =IF(I29="Required","Required",IF(ISNUMBER(MATCH(J29,Lists!$H$2:$H$9,0)),I29,"")) | L29: =IF(I29="Required","Required",IF(ISNUMBER(MATCH(J29,Lists!$I$2:$I$9,0)),I29,IF(ISNUMBER(MATCH(J29,Lists!$J$2:$J$9,0)),I29,""))) | Q29: =IF(I29="Required",0,IF(ISNUMBER(MATCH(J29,Lists!$I$2:$I$4,0)),L29)) -> FALSE | R29: =IF(I29="Required",0,IF(ISNUMBER(MATCH(J29,Lists!$K$2:$K$7,0)),L29)) -> FALSE | S29: =IF(I29="Required",0,IF(ISNUMBER(MATCH(J29,Lists!$G$2:$G$4,0)),L29)) -> FALSE | T29: =IF(I29="Required",0,IF(ISNUMBER(MATCH(J29,Lists!$G$7:$G$8,0)),L29)) -> FALSE | U29: =IF(I29="Required",0,IF(ISNUMBER(MATCH(J29,Lists!$H$2:$H$4,0)),K29)) -> FALSE | V29: =IF(A29="P",IF(IFERROR(SEARCH("Pending Documentation",J29),0)>0,IF(I29="Required",1,I29),0),0) -> 0 | W29: =IF(A29="P",IF(IFERROR(SEARCH("Pending On-site Assessment",J29),0)>0,IF(I29="Required",1,I29),0),0) -> 0
A30: O | F30: A07.3 / 1 Point Apply Universal Design to Windows | G30: ='Review Comments'!F29 -> 0 | H30: ='Review Comments'!G29 -> No | I30: =IF(H30="Yes",G30,IF(H30="Required","Required","")) | J30: =IF('Review Comments'!H29=0,"",'Review Comments'!H29) -> Not Attempted | K30: =IF(I30="Required","Required",IF(ISNUMBER(MATCH(J30,Lists!$H$2:$H$9,0)),I30,"")) | L30: =IF(I30="Required","Required",IF(ISNUMBER(MATCH(J30,Lists!$I$2:$I$9,0)),I30,IF(ISNUMBER(MATCH(J30,Lists!$J$2:$J$9,0)),I30,""))) | Q30: =IF(I30="Required",0,IF(ISNUMBER(MATCH(J30,Lists!$I$2:$I$4,0)),L30)) -> FALSE | R30: =IF(I30="Required",0,IF(ISNUMBER(MATCH(J30,Lists!$K$2:$K$7,0)),L30)) -> FALSE | S30: =IF(I30="Required",0,IF(ISNUMBER(MATCH(J30,Lists!$G$2:$G$4,0)),L30)) -> FALSE | T30: =IF(I30="Required",0,IF(ISNUMBER(MATCH(J30,Lists!$G$7:$G$8,0)),L30)) -> FALSE | U30: =IF(I30="Required",0,IF(ISNUMBER(MATCH(J30,Lists!$H$2:$H$4,0)),K30)) -> FALSE | V30: =IF(A30="P",IF(IFERROR(SEARCH("Pending Documentation",J30),0)>0,IF(I30="Required",1,I30),0),0) -> 0 | W30: =IF(A30="P",IF(IFERROR(SEARCH("Pending On-site Assessment",J30),0)>0,IF(I30="Required",1,I30),0),0) -> 0
A31: O | D31: O | E31: A08. Air Quality Monitoring and Awareness | F31: A08.1 / 1 Point Implement Indoor Air Monitors | G31: ='Review Comments'!F30 -> 1 | H31: ='Review Comments'!G30 -> Yes | I31: =IF(H31="Yes",G31,IF(H31="Required","Required","")) -> 1 | J31: =IF('Review Comments'!H30=0,"",'Review Comments'!H30) -> Anticipated | K31: =IF(I31="Required","Required",IF(ISNUMBER(MATCH(J31,Lists!$H$2:$H$9,0)),I31,"")) -> 1 | L31: =IF(I31="Required","Required",IF(ISNUMBER(MATCH(J31,Lists!$I$2:$I$9,0)),I31,IF(ISNUMBER(MATCH(J31,Lists!$J$2:$J$9,0)),I31,""))) | Q31: =IF(I31="Required",0,IF(ISNUMBER(MATCH(J31,Lists!$I$2:$I$4,0)),L31)) -> FALSE | R31: =IF(I31="Required",0,IF(ISNUMBER(MATCH(J31,Lists!$K$2:$K$7,0)),L31)) -> FALSE | S31: =IF(I31="Required",0,IF(ISNUMBER(MATCH(J31,Lists!$G$2:$G$4,0)),L31)) -> FALSE | T31: =IF(I31="Required",0,IF(ISNUMBER(MATCH(J31,Lists!$G$7:$G$8,0)),L31)) -> FALSE | U31: =IF(I31="Required",0,IF(ISNUMBER(MATCH(J31,Lists!$H$2:$H$4,0)),K31)) -> 1 | V31: =IF(A31="P",IF(IFERROR(SEARCH("Pending Documentation",J31),0)>0,IF(I31="Required",1,I31),0),0) -> 0 | W31: =IF(A31="P",IF(IFERROR(SEARCH("Pending On-site Assessment",J31),0)>0,IF(I31="Required",1,I31),0),0) -> 0
A32: O | F32: A08.2 / 1 Point Promote Air Quality Awareness | G32: ='Review Comments'!F31 -> 1 | H32: ='Review Comments'!G31 -> Yes | I32: =IF(H32="Yes",G32,IF(H32="Required","Required","")) -> 1 | J32: =IF('Review Comments'!H31=0,"",'Review Comments'!H31) -> Anticipated | K32: =IF(I32="Required","Required",IF(ISNUMBER(MATCH(J32,Lists!$H$2:$H$9,0)),I32,"")) -> 1 | L32: =IF(I32="Required","Required",IF(ISNUMBER(MATCH(J32,Lists!$I$2:$I$9,0)),I32,IF(ISNUMBER(MATCH(J32,Lists!$J$2:$J$9,0)),I32,""))) | Q32: =IF(I32="Required",0,IF(ISNUMBER(MATCH(J32,Lists!$I$2:$I$4,0)),L32)) -> FALSE | R32: =IF(I32="Required",0,IF(ISNUMBER(MATCH(J32,Lists!$K$2:$K$7,0)),L32)) -> FALSE | S32: =IF(I32="Required",0,IF(ISNUMBER(MATCH(J32,Lists!$G$2:$G$4,0)),L32)) -> FALSE | T32: =IF(I32="Required",0,IF(ISNUMBER(MATCH(J32,Lists!$G$7:$G$8,0)),L32)) -> FALSE | U32: =IF(I32="Required",0,IF(ISNUMBER(MATCH(J32,Lists!$H$2:$H$4,0)),K32)) -> 1 | V32: =IF(A32="P",IF(IFERROR(SEARCH("Pending Documentation",J32),0)>0,IF(I32="Required",1,I32),0),0) -> 0 | W32: =IF(A32="P",IF(IFERROR(SEARCH("Pending On-site Assessment",J32),0)>0,IF(I32="Required",1,I32),0),0) -> 0
A33: O | D33: O | E33: A09. Pollution Infiltration Management | F33: A09.1 / 1 Point Design Healthy Envelope and Entryways | G33: ='Review Comments'!F32 -> 1 | H33: ='Review Comments'!G32 -> Yes | I33: =IF(H33="Yes",G33,IF(H33="Required","Required","")) -> 1 | J33: =IF('Review Comments'!H32=0,"",'Review Comments'!H32) -> Anticipated | K33: =IF(I33="Required","Required",IF(ISNUMBER(MATCH(J33,Lists!$H$2:$H$9,0)),I33,"")) -> 1 | L33: =IF(I33="Required","Required",IF(ISNUMBER(MATCH(J33,Lists!$I$2:$I$9,0)),I33,IF(ISNUMBER(MATCH(J33,Lists!$J$2:$J$9,0)),I33,""))) | Q33: =IF(I33="Required",0,IF(ISNUMBER(MATCH(J33,Lists!$I$2:$I$4,0)),L33)) -> FALSE | R33: =IF(I33="Required",0,IF(ISNUMBER(MATCH(J33,Lists!$K$2:$K$7,0)),L33)) -> FALSE | S33: =IF(I33="Required",0,IF(ISNUMBER(MATCH(J33,Lists!$G$2:$G$4,0)),L33)) -> FALSE | T33: =IF(I33="Required",0,IF(ISNUMBER(MATCH(J33,Lists!$G$7:$G$8,0)),L33)) -> FALSE | U33: =IF(I33="Required",0,IF(ISNUMBER(MATCH(J33,Lists!$H$2:$H$4,0)),K33)) -> 1 | V33: =IF(A33="P",IF(IFERROR(SEARCH("Pending Documentation",J33),0)>0,IF(I33="Required",1,I33),0),0) -> 0 | W33: =IF(A33="P",IF(IFERROR(SEARCH("Pending On-site Assessment",J33),0)>0,IF(I33="Required",1,I33),0),0) -> 0
A34: O | D34: O | E34: A10. Combustion Minimization | F34: A10.1 / 1 Point Manage Combustion | G34: ='Review Comments'!F33 -> 1 | H34: ='Review Comments'!G33 -> Yes | I34: =IF(H34="Yes",G34,IF(H34="Required","Required","")) -> 1 | J34: =IF('Review Comments'!H33=0,"",'Review Comments'!H33) -> Anticipated | K34: =IF(I34="Required","Required",IF(ISNUMBER(MATCH(J34,Lists!$H$2:$H$9,0)),I34,"")) -> 1 | L34: =IF(I34="Required","Required",IF(ISNUMBER(MATCH(J34,Lists!$I$2:$I$9,0)),I34,IF(ISNUMBER(MATCH(J34,Lists!$J$2:$J$9,0)),I34,""))) | Q34: =IF(I34="Required",0,IF(ISNUMBER(MATCH(J34,Lists!$I$2:$I$4,0)),L34)) -> FALSE | R34: =IF(I34="Required",0,IF(ISNUMBER(MATCH(J34,Lists!$K$2:$K$7,0)),L34)) -> FALSE | S34: =IF(I34="Required",0,IF(ISNUMBER(MATCH(J34,Lists!$G$2:$G$4,0)),L34)) -> FALSE | T34: =IF(I34="Required",0,IF(ISNUMBER(MATCH(J34,Lists!$G$7:$G$8,0)),L34)) -> FALSE | U34: =IF(I34="Required",0,IF(ISNUMBER(MATCH(J34,Lists!$H$2:$H$4,0)),K34)) -> 1 | V34: =IF(A34="P",IF(IFERROR(SEARCH("Pending Documentation",J34),0)>0,IF(I34="Required",1,I34),0),0) -> 0 | W34: =IF(A34="P",IF(IFERROR(SEARCH("Pending On-site Assessment",J34),0)>0,IF(I34="Required",1,I34),0),0) -> 0
A35: O | D35: O | E35: A11. Source Separation | F35: A11.1 / 1 Point Manage Pollution and Exhaust | G35: ='Review Comments'!F34 -> 1 | H35: ='Review Comments'!G34 -> Yes | I35: =IF(H35="Yes",G35,IF(H35="Required","Required","")) -> 1 | J35: =IF('Review Comments'!H34=0,"",'Review Comments'!H34) -> Anticipated | K35: =IF(I35="Required","Required",IF(ISNUMBER(MATCH(J35,Lists!$H$2:$H$9,0)),I35,"")) -> 1 | L35: =IF(I35="Required","Required",IF(ISNUMBER(MATCH(J35,Lists!$I$2:$I$9,0)),I35,IF(ISNUMBER(MATCH(J35,Lists!$J$2:$J$9,0)),I35,""))) | Q35: =IF(I35="Required",0,IF(ISNUMBER(MATCH(J35,Lists!$I$2:$I$4,0)),L35)) -> FALSE | R35: =IF(I35="Required",0,IF(ISNUMBER(MATCH(J35,Lists!$K$2:$K$7,0)),L35)) -> FALSE | S35: =IF(I35="Required",0,IF(ISNUMBER(MATCH(J35,Lists!$G$2:$G$4,0)),L35)) -> FALSE | T35: =IF(I35="Required",0,IF(ISNUMBER(MATCH(J35,Lists!$G$7:$G$8,0)),L35)) -> FALSE | U35: =IF(I35="Required",0,IF(ISNUMBER(MATCH(J35,Lists!$H$2:$H$4,0)),K35)) -> 1 | V35: =IF(A35="P",IF(IFERROR(SEARCH("Pending Documentation",J35),0)>0,IF(I35="Required",1,I35),0),0) -> 0 | W35: =IF(A35="P",IF(IFERROR(SEARCH("Pending On-site Assessment",J35),0)>0,IF(I35="Required",1,I35),0),0) -> 0
A36: O | D36: O | E36: A12. Air Filtration | F36: A12.1 / 1 Point Implement Particle Filtration | G36: ='Review Comments'!F35 -> 1 | H36: ='Review Comments'!G35 -> Yes | I36: =IF(H36="Yes",G36,IF(H36="Required","Required","")) -> 1 | J36: =IF('Review Comments'!H35=0,"",'Review Comments'!H35) -> Anticipated | K36: =IF(I36="Required","Required",IF(ISNUMBER(MATCH(J36,Lists!$H$2:$H$9,0)),I36,"")) -> 1 | L36: =IF(I36="Required","Required",IF(ISNUMBER(MATCH(J36,Lists!$I$2:$I$9,0)),I36,IF(ISNUMBER(MATCH(J36,Lists!$J$2:$J$9,0)),I36,""))) | Q36: =IF(I36="Required",0,IF(ISNUMBER(MATCH(J36,Lists!$I$2:$I$4,0)),L36)) -> FALSE | R36: =IF(I36="Required",0,IF(ISNUMBER(MATCH(J36,Lists!$K$2:$K$7,0)),L36)) -> FALSE | S36: =IF(I36="Required",0,IF(ISNUMBER(MATCH(J36,Lists!$G$2:$G$4,0)),L36)) -> FALSE | T36: =IF(I36="Required",0,IF(ISNUMBER(MATCH(J36,Lists!$G$7:$G$8,0)),L36)) -> FALSE | U36: =IF(I36="Required",0,IF(ISNUMBER(MATCH(J36,Lists!$H$2:$H$4,0)),K36)) -> 1 | V36: =IF(A36="P",IF(IFERROR(SEARCH("Pending Documentation",J36),0)>0,IF(I36="Required",1,I36),0),0) -> 0 | W36: =IF(A36="P",IF(IFERROR(SEARCH("Pending On-site Assessment",J36),0)>0,IF(I36="Required",1,I36),0),0) -> 0
A37: O | D37: O | E37: A13. Active VOC Control | F37: A13.1 / 1 Point Implement Carbon Filtration | G37: ='Review Comments'!F36 -> 1 | H37: ='Review Comments'!G36 -> Yes | I37: =IF(H37="Yes",G37,IF(H37="Required","Required","")) -> 1 | J37: =IF('Review Comments'!H36=0,"",'Review Comments'!H36) -> Anticipated | K37: =IF(I37="Required","Required",IF(ISNUMBER(MATCH(J37,Lists!$H$2:$H$9,0)),I37,"")) -> 1 | L37: =IF(I37="Required","Required",IF(ISNUMBER(MATCH(J37,Lists!$I$2:$I$9,0)),I37,IF(ISNUMBER(MATCH(J37,Lists!$J$2:$J$9,0)),I37,""))) | Q37: =IF(I37="Required",0,IF(ISNUMBER(MATCH(J37,Lists!$I$2:$I$4,0)),L37)) -> FALSE | R37: =IF(I37="Required",0,IF(ISNUMBER(MATCH(J37,Lists!$K$2:$K$7,0)),L37)) -> FALSE | S37: =IF(I37="Required",0,IF(ISNUMBER(MATCH(J37,Lists!$G$2:$G$4,0)),L37)) -> FALSE | T37: =IF(I37="Required",0,IF(ISNUMBER(MATCH(J37,Lists!$G$7:$G$8,0)),L37)) -> FALSE | U37: =IF(I37="Required",0,IF(ISNUMBER(MATCH(J37,Lists!$H$2:$H$4,0)),K37)) -> 1 | V37: =IF(A37="P",IF(IFERROR(SEARCH("Pending Documentation",J37),0)>0,IF(I37="Required",1,I37),0),0) -> 0 | W37: =IF(A37="P",IF(IFERROR(SEARCH("Pending On-site Assessment",J37),0)>0,IF(I37="Required",1,I37),0),0) -> 0
A38: O | D38: O | E38: A14. Microbe and Mold Control | F38: A14.1 / 1 Point Implement Ultraviolet Air Treatment | G38: ='Review Comments'!F37 -> 1 | H38: ='Review Comments'!G37 -> Yes | I38: =IF(H38="Yes",G38,IF(H38="Required","Required","")) -> 1 | J38: =IF('Review Comments'!H37=0,"",'Review Comments'!H37) -> Anticipated | K38: =IF(I38="Required","Required",IF(ISNUMBER(MATCH(J38,Lists!$H$2:$H$9,0)),I38,"")) -> 1 | L38: =IF(I38="Required","Required",IF(ISNUMBER(MATCH(J38,Lists!$I$2:$I$9,0)),I38,IF(ISNUMBER(MATCH(J38,Lists!$J$2:$J$9,0)),I38,""))) | Q38: =IF(I38="Required",0,IF(ISNUMBER(MATCH(J38,Lists!$I$2:$I$4,0)),L38)) -> FALSE | R38: =IF(I38="Required",0,IF(ISNUMBER(MATCH(J38,Lists!$K$2:$K$7,0)),L38)) -> FALSE | S38: =IF(I38="Required",0,IF(ISNUMBER(MATCH(J38,Lists!$G$2:$G$4,0)),L38)) -> FALSE | T38: =IF(I38="Required",0,IF(ISNUMBER(MATCH(J38,Lists!$G$7:$G$8,0)),L38)) -> FALSE | U38: =IF(I38="Required",0,IF(ISNUMBER(MATCH(J38,Lists!$H$2:$H$4,0)),K38)) -> 1 | V38: =IF(A38="P",IF(IFERROR(SEARCH("Pending Documentation",J38),0)>0,IF(I38="Required",1,I38),0),0) -> 0 | W38: =IF(A38="P",IF(IFERROR(SEARCH("Pending On-site Assessment",J38),0)>0,IF(I38="Required",1,I38),0),0) -> 0
A39: O | F39: A14.2 / 1 Point Manage Condensation and Mold | G39: ='Review Comments'!F38 -> 1 | H39: ='Review Comments'!G38 -> Yes | I39: =IF(H39="Yes",G39,IF(H39="Required","Required","")) -> 1 | J39: =IF('Review Comments'!H38=0,"",'Review Comments'!H38) -> Anticipated | K39: =IF(I39="Required","Required",IF(ISNUMBER(MATCH(J39,Lists!$H$2:$H$9,0)),I39,"")) -> 1 | L39: =IF(I39="Required","Required",IF(ISNUMBER(MATCH(J39,Lists!$I$2:$I$9,0)),I39,IF(ISNUMBER(MATCH(J39,Lists!$J$2:$J$9,0)),I39,""))) | Q39: =IF(I39="Required",0,IF(ISNUMBER(MATCH(J39,Lists!$I$2:$I$4,0)),L39)) -> FALSE | R39: =IF(I39="Required",0,IF(ISNUMBER(MATCH(J39,Lists!$K$2:$K$7,0)),L39)) -> FALSE | S39: =IF(I39="Required",0,IF(ISNUMBER(MATCH(J39,Lists!$G$2:$G$4,0)),L39)) -> FALSE | T39: =IF(I39="Required",0,IF(ISNUMBER(MATCH(J39,Lists!$G$7:$G$8,0)),L39)) -> FALSE | U39: =IF(I39="Required",0,IF(ISNUMBER(MATCH(J39,Lists!$H$2:$H$4,0)),K39)) -> 1 | V39: =IF(A39="P",IF(IFERROR(SEARCH("Pending Documentation",J39),0)>0,IF(I39="Required",1,I39),0),0) -> 0 | W39: =IF(A39="P",IF(IFERROR(SEARCH("Pending On-site Assessment",J39),0)>0,IF(I39="Required",1,I39),0),0) -> 0
A40: O | G40: =SUM(G11:G39) -> 12 | I40: =SUM(I11:I39) -> 12 | K40: =SUM(K11:K39) -> 12 | L40: =SUM(L11:L39) -> 0 | Q40: =IF(I40="Required",0,IF(ISNUMBER(MATCH(J40,Lists!$I$2:$I$4,0)),L40)) -> FALSE | R40: =IF(I40="Required",0,IF(ISNUMBER(MATCH(J40,Lists!$K$2:$K$7,0)),L40)) -> FALSE | S40: =IF(I40="Required",0,IF(ISNUMBER(MATCH(J40,Lists!$G$2:$G$4,0)),L40)) -> FALSE | T40: =IF(I40="Required",0,IF(ISNUMBER(MATCH(J40,Lists!$G$7:$G$8,0)),L40)) -> FALSE | U40: =IF(I40="Required",0,IF(ISNUMBER(MATCH(J40,Lists!$H$2:$H$4,0)),K40)) -> FALSE | V40: =IF(A40="P",IF(IFERROR(SEARCH("Pending Documentation",J40),0)>0,IF(I40="Required",1,I40),0),0) -> 0 | W40: =IF(A40="P",IF(IFERROR(SEARCH("Pending On-site Assessment",J40),0)>0,IF(I40="Required",1,I40),0),0) -> 0
Q41: =IF(I41="Required",0,IF(ISNUMBER(MATCH(J41,Lists!$I$2:$I$4,0)),L41)) -> FALSE | R41: =IF(I41="Required",0,IF(ISNUMBER(MATCH(J41,Lists!$K$2:$K$7,0)),L41)) -> FALSE | S41: =IF(I41="Required",0,IF(ISNUMBER(MATCH(J41,Lists!$G$2:$G$4,0)),L41)) -> FALSE | T41: =IF(I41="Required",0,IF(ISNUMBER(MATCH(J41,Lists!$G$7:$G$8,0)),L41)) -> FALSE | U41: =IF(I41="Required",0,IF(ISNUMBER(MATCH(J41,Lists!$H$2:$H$4,0)),K41)) -> FALSE | V41: =IF(A41="P",IF(IFERROR(SEARCH("Pending Documentation",J41),0)>0,IF(I41="Required",1,I41),0),0) -> 0 | W41: =IF(A41="P",IF(IFERROR(SEARCH("Pending On-site Assessment",J41),0)>0,IF(I41="Required",1,I41),0),0) -> 0
...

Sheet Review Comments
F1: Hide these columns before printing to PDF
B2: =Overview!C1 -> 2202025367 - Shenzhen Prince Bay Mixed-use Development DY04-02
B4: Concept | C4: Type | D4: Feature | E4: Part | F4: Points Attempted | G4: Pursuing | H4: Status | I4: Review Comment
B5: General Project Observations:
B6: Additional clarifications provided were concise and addressed the issues noted in the Preliminary Precertification Review report. All parts have been reviewed and no additional clarifications are required at this time. Congratulations on achieving WELL Precertification! It has been noted that the retail, commercial kitchen, and commercial dining spaces are not under the control of the WELL Project Owner and the requirements for these space types are not applicable to this WELL project. Please remove these space types from the Overview tab prior to submitting for Preliminary Documentation Review. | L6: Status and TA MISMATCH | M6: PV and Status MISMATCH | N6: Anticipated/PV MISMATCH | O6: Not Attempted and Comment MISMATCH | P6: TA Match | Q6: TA Status | R6: PV Match | S6: PV Status | T6: Special Rule Flags
C8: Air General Observations:
B10: AIR | C10: P | D10: A01. Fundamental Air Quality | E10: A01.1 Meet Thresholds for Particulate Matter | G10: Required | H10: Anticipated | I10: PRELIMINARY PRECERTIFICATION REVIEW: Implementation-stage has no required documentation. | L10: =IF(OR(Overview!$D$4="Preliminary Documentation Review",Overview!$D$4="Preliminary Precertification Review"),IF(AND(P10=0,Q10=0),"",IF(AND(P10>0,Q10>0),"","MISMATCH")),"") | M10: =IF(OR(Overview!$D$4="Preliminary Documentation Review",Overview!$D$4="Preliminary Precertification Review"),IF(AND(R10=0,S10=0),"",IF(AND(R10>0,S10>0),"","MISMATCH")),"") | N10: =IF(OR(Overview!$D$4="Preliminary Documentation Review",Overview!$D$4="Preliminary Precertification Review"),IF(AND(T10=0,U10=0),"",IF(AND(T10>0,U10>0),"MISMATCH","")),"") | O10: =IF(OR(Overview!$D$4="Preliminary Documentation Review",Overview!$D$4="Preliminary Precertification Review"),IF(AND(V10=0,W10=0),"",IF(AND(V10>0,W10>0),"","MISMATCH")),"") | P10: =IFERROR(SEARCH("COMMENTS TO BE ADDRESS",$I10),0) -> 0 | Q10: =IFERROR(SEARCH("Pending Documentation",$H10),0) -> 0 | R10: =IFERROR(SEARCH("equirements of this part will be v",$I10),0) -> 0 | S10: =IFERROR(SEARCH("Pending On",$H10),0) -> 0 | T10: =IFERROR(SEARCH("This Part has no",$I10),0) -> 0 | U10: =IFERROR(SEARCH("Anticipated",$H10),0) -> 1 | V10: =IFERROR(SEARCH("This Part has not been attempted.",$I10),IFERROR(SEARCH("Not Attempted",$I10),0)) -> 0 | W10: =IFERROR(SEARCH("Not Attempted",$H10),0) -> 0
E11: A01.2 Meet Thresholds for Organic Gases | G11: Required | H11: Anticipated | I11: PRELIMINARY PRECERTIFICATION REVIEW: Implementation-stage has no required documentation. | L11: =IF(OR(Overview!$D$4="Preliminary Documentation Review",Overview!$D$4="Preliminary Precertification Review"),IF(AND(P11=0,Q11=0),"",IF(AND(P11>0,Q11>0),"","MISMATCH")),"") | M11: =IF(OR(Overview!$D$4="Preliminary Documentation Review",Overview!$D$4="Preliminary Precertification Review"),IF(AND(R11=0,S11=0),"",IF(AND(R11>0,S11>0),"","MISMATCH")),"") | N11: =IF(OR(Overview!$D$4="Preliminary Documentation Review",Overview!$D$4="Preliminary Precertification Review"),IF(AND(T11=0,U11=0),"",IF(AND(T11>0,U11>0),"MISMATCH","")),"") | O11: =IF(OR(Overview!$D$4="Preliminary Documentation Review",Overview!$D$4="Preliminary Precertification Review"),IF(AND(V11=0,W11=0),"",IF(AND(V11>0,W11>0),"","MISMATCH")),"") | P11: =IFERROR(SEARCH("COMMENTS TO BE ADDRESS",$I11),0) -> 0 | Q11: =IFERROR(SEARCH("Pending Documentation",$H11),0) -> 0 | R11: =IFERROR(SEARCH("equirements of this part will be v",$I11),0) -> 0 | S11: =IFERROR(SEARCH("Pending On",$H11),0) -> 0 | T11: =IFERROR(SEARCH("This Part has no",$I11),0) -> 0 | U11: =IFERROR(SEARCH("Anticipated",$H11),0) -> 1 | V11: =IFERROR(SEARCH("This Part has not been attempted.",$I11),IFERROR(SEARCH("Not Attempted",$I11),0)) -> 0 | W11: =IFERROR(SEARCH("Not Attempted",$H11),0) -> 0
E12: A01.3 Meet Thresholds for Inorganic Gases | G12: Required | H12: Anticipated | I12: PRELIMINARY PRECERTIFICATION REVIEW: Implementation-stage has no required documentation. | L12: =IF(OR(Overview!$D$4="Preliminary Documentation Review",Overview!$D$4="Preliminary Precertification Review"),IF(AND(P12=0,Q12=0),"",IF(AND(P12>0,Q12>0),"","MISMATCH")),"") | M12: =IF(OR(Overview!$D$4="Preliminary Documentation Review",Overview!$D$4="Preliminary Precertification Review"),IF(AND(R12=0,S12=0),"",IF(AND(R12>0,S12>0),"","MISMATCH")),"") | N12: =IF(OR(Overview!$D$4="Preliminary Documentation Review",Overview!$D$4="Preliminary Precertification Review"),IF(AND(T12=0,U12=0),"",IF(AND(T12>0,U12>0),"MISMATCH","")),"") | O12: =IF(OR(Overview!$D$4="Preliminary Documentation Review",Overview!$D$4="Preliminary Precertification Review"),IF(AND(V12=0,W12=0),"",IF(AND(V12>0,W12>0),"","MISMATCH")),"") | P12: =IFERROR(SEARCH("COMMENTS TO BE ADDRESS",$I12),0) -> 0 | Q12: =IFERROR(SEARCH("Pending Documentation",$H12),0) -> 0 | R12: =IFERROR(SEARCH("equirements of this part will be v",$I12),0) -> 0 | S12: =IFERROR(SEARCH("Pending On",$H12),0) -> 0 | T12: =IFERROR(SEARCH("This Part has no",$I12),0) -> 0 | U12: =IFERROR(SEARCH("Anticipated",$H12),0) -> 1 | V12: =IFERROR(SEARCH("This Part has not been attempted.",$I12),IFERROR(SEARCH("Not Attempted",$I12),0)) -> 0 | W12: =IFERROR(SEARCH("Not Attempted",$H12),0) -> 0
E13: A01.4 Meet Radon Threshold | G13: Required | H13: Anticipated | I13: PRELIMINARY PRECERTIFICATION REVIEW: Intent-stage documentation has been provided indicating that the part requirements will be met. Note the following. I. This part is dependent on achieving the 'Mechanically ventilated spaces' option of Part 1: Ensure Adequate Ventilation in Feature A03: Ventilation Effectiveness. | L13: =IF(OR(Overview!$D$4="Preliminary Documentation Review",Overview!$D$4="Preliminary Precertification Review"),IF(AND(P13=0,Q13=0),"",IF(AND(P13>0,Q13>0),"","MISMATCH")),"") | M13: =IF(OR(Overview!$D$4="Preliminary Documentation Review",Overview!$D$4="Preliminary Precertification Review"),IF(AND(R13=0,S13=0),"",IF(AND(R13>0,S13>0),"","MISMATCH")),"") | N13: =IF(OR(Overview!$D$4="Preliminary Documentation Review",Overview!$D$4="Preliminary Precertification Review"),IF(AND(T13=0,U13=0),"",IF(AND(T13>0,U13>0),"MISMATCH","")),"") | O13: =IF(OR(Overview!$D$4="Preliminary Documentation Review",Overview!$D$4="Preliminary Precertification Review"),IF(AND(V13=0,W13=0),"",IF(AND(V13>0,W13>0),"","MISMATCH")),"") | P13: =IFERROR(SEARCH("COMMENTS TO BE ADDRESS",$I13),0) -> 0 | Q13: =IFERROR(SEARCH("Pending Documentation",$H13),0) -> 0 | R13: =IFERROR(SEARCH("equirements of this part will be v",$I13),0) -> 0 | S13: =IFERROR(SEARCH("Pending On",$H13),0) -> 0 | T13: =IFERROR(SEARCH("This Part has no",$I13),0) -> 0 | U13: =IFERROR(SEARCH("Anticipated",$H13),0) -> 1 | V13: =IFERROR(SEARCH("This Part has not been attempted.",$I13),IFERROR(SEARCH("Not Attempted",$I13),0)) -> 0 | W13: =IFERROR(SEARCH("Not Attempted",$H13),0) -> 0
E14: A01.5 Monitor Fundamental Air Parameters | G14: Required | H14: Anticipated | I14: PRELIMINARY PRECERTIFICATION REVIEW: Implementation-stage documentation has been provided. | L14: =IF(OR(Overview!$D$4="Preliminary Documentation Review",Overview!$D$4="Preliminary Precertification Review"),IF(AND(P14=0,Q14=0),"",IF(AND(P14>0,Q14>0),"","MISMATCH")),"") | M14: =IF(OR(Overview!$D$4="Preliminary Documentation Review",Overview!$D$4="Preliminary Precertification Review"),IF(AND(R14=0,S14=0),"",IF(AND(R14>0,S14>0),"","MISMATCH")),"") | N14: =IF(OR(Overview!$D$4="Preliminary Documentation Review",Overview!$D$4="Preliminary Precertification Review"),IF(AND(T14=0,U14=0),"",IF(AND(T14>0,U14>0),"MISMATCH","")),"") | O14: =IF(OR(Overview!$D$4="Preliminary Documentation Review",Overview!$D$4="Preliminary Precertification Review"),IF(AND(V14=0,W14=0),"",IF(AND(V14>0,W14>0),"","MISMATCH")),"") | P14: =IFERROR(SEARCH("COMMENTS TO BE ADDRESS",$I14),0) -> 0 | Q14: =IFERROR(SEARCH("Pending Documentation",$H14),0) -> 0 | R14: =IFERROR(SEARCH("equirements of this part will be v",$I14),0) -> 0 | S14: =IFERROR(SEARCH("Pending On",$H14),0) -> 0 | T14: =IFERROR(SEARCH("This Part has no",$I14),0) -> 0 | U14: =IFERROR(SEARCH("Anticipated",$H14),0) -> 1 | V14: =IFERROR(SEARCH("This Part has not been attempted.",$I14),IFERROR(SEARCH("Not Attempted",$I14),0)) -> 0 | W14: =IFERROR(SEARCH("Not Attempted",$H14),0) -> 0
C15: P | D15: A02. Smoke-Free Environment | E15: A02.1 Prohibit Indoor Smoking | G15: Required | H15: Anticipated | I15: PRELIMINARY PRECERTIFICATION REVIEW: Implementation-stage documentation has been provided. | L15: =IF(OR(Overview!$D$4="Preliminary Documentation Review",Overview!$D$4="Preliminary Precertification Review"),IF(AND(P15=0,Q15=0),"",IF(AND(P15>0,Q15>0),"","MISMATCH")),"") | M15: =IF(OR(Overview!$D$4="Preliminary Documentation Review",Overview!$D$4="Preliminary Precertification Review"),IF(AND(R15=0,S15=0),"",IF(AND(R15>0,S15>0),"","MISMATCH")),"") | N15: =IF(OR(Overview!$D$4="Preliminary Documentation Review",Overview!$D$4="Preliminary Precertification Review"),IF(AND(T15=0,U15=0),"",IF(AND(T15>0,U15>0),"MISMATCH","")),"") | O15: =IF(OR(Overview!$D$4="Preliminary Documentation Review",Overview!$D$4="Preliminary Precertification Review"),IF(AND(V15=0,W15=0),"",IF(AND(V15>0,W15>0),"","MISMATCH")),"") | P15: =IFERROR(SEARCH("COMMENTS TO BE ADDRESS",$I15),0) -> 0 | Q15: =IFERROR(SEARCH("Pending Documentation",$H15),0) -> 0 | R15: =IFERROR(SEARCH("equirements of this part will be v",$I15),0) -> 0 | S15: =IFERROR(SEARCH("Pending On",$H15),0) -> 0 | T15: =IFERROR(SEARCH("This Part has no",$I15),0) -> 0 | U15: =IFERROR(SEARCH("Anticipated",$H15),0) -> 1 | V15: =IFERROR(SEARCH("This Part has not been attempted.",$I15),IFERROR(SEARCH("Not Attempted",$I15),0)) -> 0 | W15: =IFERROR(SEARCH("Not Attempted",$H15),0) -> 0
E16: A02.2 Prohibit Outdoor Smoking | G16: Required | H16: Anticipated | I16: PRELIMINARY PRECERTIFICATION REVIEW: Implementation-stage has no required documentation. | L16: =IF(OR(Overview!$D$4="Preliminary Documentation Review",Overview!$D$4="Preliminary Precertification Review"),IF(AND(P16=0,Q16=0),"",IF(AND(P16>0,Q16>0),"","MISMATCH")),"") | M16: =IF(OR(Overview!$D$4="Preliminary Documentation Review",Overview!$D$4="Preliminary Precertification Review"),IF(AND(R16=0,S16=0),"",IF(AND(R16>0,S16>0),"","MISMATCH")),"") | N16: =IF(OR(Overview!$D$4="Preliminary Documentation Review",Overview!$D$4="Preliminary Precertification Review"),IF(AND(T16=0,U16=0),"",IF(AND(T16>0,U16>0),"MISMATCH","")),"") | O16: =IF(OR(Overview!$D$4="Preliminary Documentation Review",Overview!$D$4="Preliminary Precertification Review"),IF(AND(V16=0,W16=0),"",IF(AND(V16>0,W16>0),"","MISMATCH")),"") | P16: =IFERROR(SEARCH("COMMENTS TO BE ADDRESS",$I16),0) -> 0 | Q16: =IFERROR(SEARCH("Pending Documentation",$H16),0) -> 0 | R16: =IFERROR(SEARCH("equirements of this part will be v",$I16),0) -> 0 | S16: =IFERROR(SEARCH("Pending On",$H16),0) -> 0 | T16: =IFERROR(SEARCH("This Part has no",$I16),0) -> 0 | U16: =IFERROR(SEARCH("Anticipated",$H16),0) -> 1 | V16: =IFERROR(SEARCH("This Part has not been attempted.",$I16),IFERROR(SEARCH("Not Attempted",$I16),0)) -> 0 | W16: =IFERROR(SEARCH("Not Attempted",$H16),0) -> 0
C17: P | D17: A03. Ventilation Effectiveness | E17: A03.1 Ensure Adequate Ventilation | G17: Required | H17: Anticipated | I17: PRELIMINARY PRECERTIFICATION REVIEW: Intent-stage documentation has been provided indicating that the part requirements will be met. | L17: =IF(OR(Overview!$D$4="Preliminary Documentation Review",Overview!$D$4="Preliminary Precertification Review"),IF(AND(P17=0,Q17=0),"",IF(AND(P17>0,Q17>0),"","MISMATCH")),"") | M17: =IF(OR(Overview!$D$4="Preliminary Documentation Review",Overview!$D$4="Preliminary Precertification Review"),IF(AND(R17=0,S17=0),"",IF(AND(R17>0,S17>0),"","MISMATCH")),"") | N17: =IF(OR(Overview!$D$4="Preliminary Documentation Review",Overview!$D$4="Preliminary Precertification Review"),IF(AND(T17=0,U17=0),"",IF(AND(T17>0,U17>0),"MISMATCH","")),"") | O17: =IF(OR(Overview!$D$4="Preliminary Documentation Review",Overview!$D$4="Preliminary Precertification Review"),IF(AND(V17=0,W17=0),"",IF(AND(V17>0,W17>0),"","MISMATCH")),"") | P17: =IFERROR(SEARCH("COMMENTS TO BE ADDRESS",$I17),0) -> 0 | Q17: =IFERROR(SEARCH("Pending Documentation",$H17),0) -> 0 | R17: =IFERROR(SEARCH("equirements of this part will be v",$I17),0) -> 0 | S17: =IFERROR(SEARCH("Pending On",$H17),0) -> 0 | T17: =IFERROR(SEARCH("This Part has no",$I17),0) -> 0 | U17: =IFERROR(SEARCH("Anticipated",$H17),0) -> 1 | V17: =IFERROR(SEARCH("This Part has not been attempted.",$I17),IFERROR(SEARCH("Not Attempted",$I17),0)) -> 0 | W17: =IFERROR(SEARCH("Not Attempted",$H17),0) -> 0
E18: A03.2 Conduct System Balancing for All Spaces | G18: Required | H18: Anticipated | I18: PRELIMINARY PRECERTIFICATION REVIEW: Intent-stage documentation has been provided indicating that the part requirements will be met. | L18: =IF(OR(Overview!$D$4="Preliminary Documentation Review",Overview!$D$4="Preliminary Precertification Review"),IF(AND(P18=0,Q18=0),"",IF(AND(P18>0,Q18>0),"","MISMATCH")),"") | M18: =IF(OR(Overview!$D$4="Preliminary Documentation Review",Overview!$D$4="Preliminary Precertification Review"),IF(AND(R18=0,S18=0),"",IF(AND(R18>0,S18>0),"","MISMATCH")),"") | N18: =IF(OR(Overview!$D$4="Preliminary Documentation Review",Overview!$D$4="Preliminary Precertification Review"),IF(AND(T18=0,U18=0),"",IF(AND(T18>0,U18>0),"MISMATCH","")),"") | O18: =IF(OR(Overview!$D$4="Preliminary Documentation Review",Overview!$D$4="Preliminary Precertification Review"),IF(AND(V18=0,W18=0),"",IF(AND(V18>0,W18>0),"","MISMATCH")),"") | P18: =IFERROR(SEARCH("COMMENTS TO BE ADDRESS",$I18),0) -> 0 | Q18: =IFERROR(SEARCH("Pending Documentation",$H18),0) -> 0 | R18: =IFERROR(SEARCH("equirements of this part will be v",$I18),0) -> 0 | S18: =IFERROR(SEARCH("Pending On",$H18),0) -> 0 | T18: =IFERROR(SEARCH("This Part has no",$I18),0) -> 0 | U18: =IFERROR(SEARCH("Anticipated",$H18),0) -> 1 | V18: =IFERROR(SEARCH("This Part has not been attempted.",$I18),IFERROR(SEARCH("Not Attempted",$I18),0)) -> 0 | W18: =IFERROR(SEARCH("Not Attempted",$H18),0) -> 0
C19: P | D19: A04. Construction Pollution Management | E19: A04.1 Mitigate Construction Pollution | G19: Required | H19: Anticipated | I19: PRELIMINARY PRECERTIFICATION REVIEW: Intent-stage documentation has been provided indicating that the part requirements will be met. | L19: =IF(OR(Overview!$D$4="Preliminary Documentation Review",Overview!$D$4="Preliminary Precertification Review"),IF(AND(P19=0,Q19=0),"",IF(AND(P19>0,Q19>0),"","MISMATCH")),"") | M19: =IF(OR(Overview!$D$4="Preliminary Documentation Review",Overview!$D$4="Preliminary Precertification Review"),IF(AND(R19=0,S19=0),"",IF(AND(R19>0,S19>0),"","MISMATCH")),"") | N19: =IF(OR(Overview!$D$4="Preliminary Documentation Review",Overview!$D$4="Preliminary Precertification Review"),IF(AND(T19=0,U19=0),"",IF(AND(T19>0,U19>0),"MISMATCH","")),"") | O19: =IF(OR(Overview!$D$4="Preliminary Documentation Review",Overview!$D$4="Preliminary Precertification Review"),IF(AND(V19=0,W19=0),"",IF(AND(V19>0,W19>0),"","MISMATCH")),"") | P19: =IFERROR(SEARCH("COMMENTS TO BE ADDRESS",$I19),0) -> 0 | Q19: =IFERROR(SEARCH("Pending Documentation",$H19),0) -> 0 | R19: =IFERROR(SEARCH("equirements of this part will be v",$I19),0) -> 0 | S19: =IFERROR(SEARCH("Pending On",$H19),0) -> 0 | T19: =IFERROR(SEARCH("This Part has no",$I19),0) -> 0 | U19: =IFERROR(SEARCH("Anticipated",$H19),0) -> 1 | V19: =IFERROR(SEARCH("This Part has not been attempted.",$I19),IFERROR(SEARCH("Not Attempted",$I19),0)) -> 0 | W19: =IFERROR(SEARCH("Not Attempted",$H19),0) -> 0
C20: O | D20: A05. Enhanced Air Quality | E20: A05.1 / 2 Points Meet Enhanced Thresholds for Particulate Matter | F20: 1 | G20: Yes | H20: Anticipated | I20: PRELIMINARY PRECERTIFICATION REVIEW: Implementation-stage has no required documentation. | L20: =IF(OR(Overview!$D$4="Preliminary Documentation Review",Overview!$D$4="Preliminary Precertification Review"),IF(AND(P20=0,Q20=0),"",IF(AND(P20>0,Q20>0),"","MISMATCH")),"") | M20: =IF(OR(Overview!$D$4="Preliminary Documentation Review",Overview!$D$4="Preliminary Precertification Review"),IF(AND(R20=0,S20=0),"",IF(AND(R20>0,S20>0),"","MISMATCH")),"") | N20: =IF(OR(Overview!$D$4="Preliminary Documentation Review",Overview!$D$4="Preliminary Precertification Review"),IF(AND(T20=0,U20=0),"",IF(AND(T20>0,U20>0),"MISMATCH","")),"") | O20: =IF(OR(Overview!$D$4="Preliminary Documentation Review",Overview!$D$4="Preliminary Precertification Review"),IF(AND(V20=0,W20=0),"",IF(AND(V20>0,W20>0),"","MISMATCH")),"") | P20: =IFERROR(SEARCH("COMMENTS TO BE ADDRESS",$I20),0) -> 0 | Q20: =IFERROR(SEARCH("Pending Documentation",$H20),0) -> 0 | R20: =IFERROR(SEARCH("equirements of this part will be v",$I20),0) -> 0 | S20: =IFERROR(SEARCH("Pending On",$H20),0) -> 0 | T20: =IFERROR(SEARCH("This Part has no",$I20),0) -> 0 | U20: =IFERROR(SEARCH("Anticipated",$H20),0) -> 1 | V20: =IFERROR(SEARCH("This Part has not been attempted.",$I20),IFERROR(SEARCH("Not Attempted",$I20),0)) -> 0 | W20: =IFERROR(SEARCH("Not Attempted",$H20),0) -> 0
E21: A05.2 / 1 Point Meet Enhanced Thresholds for Organic Gases | G21: No | H21: Not Attempted | I21: PRELIMINARY PRECERTIFICATION REVIEW: This part has not been attempted. | L21: =IF(OR(Overview!$D$4="Preliminary Documentation Review",Overview!$D$4="Preliminary Precertification Review"),IF(AND(P21=0,Q21=0),"",IF(AND(P21>0,Q21>0),"","MISMATCH")),"") | M21: =IF(OR(Overview!$D$4="Preliminary Documentation Review",Overview!$D$4="Preliminary Precertification Review"),IF(AND(R21=0,S21=0),"",IF(AND(R21>0,S21>0),"","MISMATCH")),"") | N21: =IF(OR(Overview!$D$4="Preliminary Documentation Review",Overview!$D$4="Preliminary Precertification Review"),IF(AND(T21=0,U21=0),"",IF(AND(T21>0,U21>0),"MISMATCH","")),"") | O21: =IF(OR(Overview!$D$4="Preliminary Documentation Review",Overview!$D$4="Preliminary Precertification Review"),IF(AND(V21=0,W21=0),"",IF(AND(V21>0,W21>0),"","MISMATCH")),"") | P21: =IFERROR(SEARCH("COMMENTS TO BE ADDRESS",$I21),0) -> 0 | Q21: =IFERROR(SEARCH("Pending Documentation",$H21),0) -> 0 | R21: =IFERROR(SEARCH("equirements of this part will be v",$I21),0) -> 0 | S21: =IFERROR(SEARCH("Pending On",$H21),0) -> 0 | T21: =IFERROR(SEARCH("This Part has no",$I21),0) -> 38 | U21: =IFERROR(SEARCH("Anticipated",$H21),0) -> 0 | V21: =IFERROR(SEARCH("This Part has not been attempted.",$I21),IFERROR(SEARCH("Not Attempted",$I21),0)) -> 38 | W21: =IFERROR(SEARCH("Not Attempted",$H21),0) -> 1
